Workbook

Sheet Task Tracker
A1: 🛠 Annual Maintenance Project – Task Tracker
A2: Web Development & Software Maintenance | Staging & Production Tracking
A3: # | B3: Task ID | C3: Task Title | D3: Description | E3: Category | F3: Priority | G3: Priority % | H3: Assigned To | I3: Start Date | J3: Due Date | K3: Est. Hours | L3: Actual Hours | M3: Staging Status | N3: Staging Date | O3: Prod Status | P3: Prod Date | Q3: Progress % | R3: Notes | S3: Last Updated
A4: 1 | B4: =IF(C4<>"","TASK-"&TEXT(4-3,"000"),"") | S4: =IF(C4<>"",TODAY(),"")
A5: 2 | B5: =IF(C5<>"","TASK-"&TEXT(5-3,"000"),"") | S5: =IF(C5<>"",TODAY(),"")
A6: 3 | B6: =IF(C6<>"","TASK-"&TEXT(6-3,"000"),"") | S6: =IF(C6<>"",TODAY(),"")
A7: 4 | B7: =IF(C7<>"","TASK-"&TEXT(7-3,"000"),"") | S7: =IF(C7<>"",TODAY(),"")
A8: 5 | B8: =IF(C8<>"","TASK-"&TEXT(8-3,"000"),"") | S8: =IF(C8<>"",TODAY(),"")
A9: 6 | B9: =IF(C9<>"","TASK-"&TEXT(9-3,"000"),"") | S9: =IF(C9<>"",TODAY(),"")
A10: 7 | B10: =IF(C10<>"","TASK-"&TEXT(10-3,"000"),"") | S10: =IF(C10<>"",TODAY(),"")
A11: 8 | B11: =IF(C11<>"","TASK-"&TEXT(11-3,"000"),"") | S11: =IF(C11<>"",TODAY(),"")
A12: 9 | B12: =IF(C12<>"","TASK-"&TEXT(12-3,"000"),"") | S12: =IF(C12<>"",TODAY(),"")
A13: 10 | B13: =IF(C13<>"","TASK-"&TEXT(13-3,"000"),"") | S13: =IF(C13<>"",TODAY(),"")
A14: 11 | B14: =IF(C14<>"","TASK-"&TEXT(14-3,"000"),"") | S14: =IF(C14<>"",TODAY(),"")
A15: 12 | B15: =IF(C15<>"","TASK-"&TEXT(15-3,"000"),"") | S15: =IF(C15<>"",TODAY(),"")
A16: 13 | B16: =IF(C16<>"","TASK-"&TEXT(16-3,"000"),"") | S16: =IF(C16<>"",TODAY(),"")
A17: 14 | B17: =IF(C17<>"","TASK-"&TEXT(17-3,"000"),"") | S17: =IF(C17<>"",TODAY(),"")
A18: 15 | B18: =IF(C18<>"","TASK-"&TEXT(18-3,"000"),"") | S18: =IF(C18<>"",TODAY(),"")
A19: 16 | B19: =IF(C19<>"","TASK-"&TEXT(19-3,"000"),"") | S19: =IF(C19<>"",TODAY(),"")
A20: 17 | B20: =IF(C20<>"","TASK-"&TEXT(20-3,"000"),"") | S20: =IF(C20<>"",TODAY(),"")
A21: 18 | B21: =IF(C21<>"","TASK-"&TEXT(21-3,"000"),"") | S21: =IF(C21<>"",TODAY(),"")
A22: 19 | B22: =IF(C22<>"","TASK-"&TEXT(22-3,"000"),"") | S22: =IF(C22<>"",TODAY(),"")
A23: 20 | B23: =IF(C23<>"","TASK-"&TEXT(23-3,"000"),"") | S23: =IF(C23<>"",TODAY(),"")
A24: 21 | B24: =IF(C24<>"","TASK-"&TEXT(24-3,"000"),"") | S24: =IF(C24<>"",TODAY(),"")
A25: 22 | B25: =IF(C25<>"","TASK-"&TEXT(25-3,"000"),"") | S25: =IF(C25<>"",TODAY(),"")
A26: 23 | B26: =IF(C26<>"","TASK-"&TEXT(26-3,"000"),"") | S26: =IF(C26<>"",TODAY(),"")
A27: 24 | B27: =IF(C27<>"","TASK-"&TEXT(27-3,"000"),"") | S27: =IF(C27<>"",TODAY(),"")
A28: 25 | B28: =IF(C28<>"","TASK-"&TEXT(28-3,"000"),"") | S28: =IF(C28<>"",TODAY(),"")
A29: 26 | B29: =IF(C29<>"","TASK-"&TEXT(29-3,"000"),"") | S29: =IF(C29<>"",TODAY(),"")
A30: 27 | B30: =IF(C30<>"","TASK-"&TEXT(30-3,"000"),"") | S30: =IF(C30<>"",TODAY(),"")
A31: 28 | B31: =IF(C31<>"","TASK-"&TEXT(31-3,"000"),"") | S31: =IF(C31<>"",TODAY(),"")
A32: 29 | B32: =IF(C32<>"","TASK-"&TEXT(32-3,"000"),"") | S32: =IF(C32<>"",TODAY(),"")
A33: 30 | B33: =IF(C33<>"","TASK-"&TEXT(33-3,"000"),"") | S33: =IF(C33<>"",TODAY(),"")
A34: 31 | B34: =IF(C34<>"","TASK-"&TEXT(34-3,"000"),"") | S34: =IF(C34<>"",TODAY(),"")
A35: 32 | B35: =IF(C35<>"","TASK-"&TEXT(35-3,"000"),"") | S35: =IF(C35<>"",TODAY(),"")
A36: 33 | B36: =IF(C36<>"","TASK-"&TEXT(36-3,"000"),"") | S36: =IF(C36<>"",TODAY(),"")
A37: 34 | B37: =IF(C37<>"","TASK-"&TEXT(37-3,"000"),"") | S37: =IF(C37<>"",TODAY(),"")
A38: 35 | B38: =IF(C38<>"","TASK-"&TEXT(38-3,"000"),"") | S38: =IF(C38<>"",TODAY(),"")
A39: 36 | B39: =IF(C39<>"","TASK-"&TEXT(39-3,"000"),"") | S39: =IF(C39<>"",TODAY(),"")
A40: 37 | B40: =IF(C40<>"","TASK-"&TEXT(40-3,"000"),"") | S40: =IF(C40<>"",TODAY(),"")
...

Sheet Dashboard
A1: 📊 Maintenance Project Dashboard
A3: KEY METRICS | D3: PRIORITY BREAKDOWN
A4: Total Tasks | B4: =COUNTA('Task Tracker'!C4:C53) | D4: Priority | E4: Total Tasks | F4: Prod Deployed | G4: Pending/Other
A5: Completed (Prod) | B5: =COUNTIF('Task Tracker'!O4:O53,"Deployed") | D5: Critical | E5: =COUNTIF('Task Tracker'!$F$4:$F$53,D5) | F5: =COUNTIFS('Task Tracker'!$F$4:$F$53,D5,'Task Tracker'!$O$4:$O$53,"Deployed") | G5: =E5-F5
A6: In Progress | B6: =COUNTIF('Task Tracker'!O4:O53,"In Progress") | D6: High | E6: =COUNTIF('Task Tracker'!$F$4:$F$53,D6) | F6: =COUNTIFS('Task Tracker'!$F$4:$F$53,D6,'Task Tracker'!$O$4:$O$53,"Deployed") | G6: =E6-F6
A7: Pending | B7: =COUNTIF('Task Tracker'!O4:O53,"Pending") | D7: Medium | E7: =COUNTIF('Task Tracker'!$F$4:$F$53,D7) | F7: =COUNTIFS('Task Tracker'!$F$4:$F$53,D7,'Task Tracker'!$O$4:$O$53,"Deployed") | G7: =E7-F7
A8: Failed / Rolled Back | B8: =COUNTIF('Task Tracker'!O4:O53,"Failed")+COUNTIF('Task Tracker'!O4:O53,"Rolled Back") | D8: Low | E8: =COUNTIF('Task Tracker'!$F$4:$F$53,D8) | F8: =COUNTIFS('Task Tracker'!$F$4:$F$53,D8,'Task Tracker'!$O$4:$O$53,"Deployed") | G8: =E8-F8
A9: Critical Tasks | B9: =COUNTIF('Task Tracker'!F4:F53,"Critical") | D9: ENVIRONMENT STATUS SUMMARY
A10: High Priority | B10: =COUNTIF('Task Tracker'!F4:F53,"High") | D10: Status | E10: Staging | F10: Production
A11: Avg Priority % | B11: =IFERROR(AVERAGEIF('Task Tracker'!C4:C53,"<>",'Task Tracker'!G4:G53),0) | D11: Pending | E11: =COUNTIF('Task Tracker'!$M$4:$M$53,D11) | F11: =COUNTIF('Task Tracker'!$O$4:$O$53,D11)
A12: Avg Progress % | B12: =IFERROR(AVERAGEIF('Task Tracker'!C4:C53,"<>",'Task Tracker'!Q4:Q53),0) | D12: In Progress | E12: =COUNTIF('Task Tracker'!$M$4:$M$53,D12) | F12: =COUNTIF('Task Tracker'!$O$4:$O$53,D12)
A13: Total Est. Hours | B13: =SUM('Task Tracker'!K4:K53) | D13: Deployed | E13: =COUNTIF('Task Tracker'!$M$4:$M$53,D13) | F13: =COUNTIF('Task Tracker'!$O$4:$O$53,D13)
A14: Total Actual Hours | B14: =SUM('Task Tracker'!L4:L53) | D14: Failed | E14: =COUNTIF('Task Tracker'!$M$4:$M$53,D14) | F14: =COUNTIF('Task Tracker'!$O$4:$O$53,D14)
A15: Overdue Tasks | B15: =SUMPRODUCT(('Task Tracker'!J4:J53<TODAY())*('Task Tracker'!O4:O53<>"Deployed")*('Task Tracker'!C4:C53<>"")) | D15: Rolled Back | E15: =COUNTIF('Task Tracker'!$M$4:$M$53,D15) | F15: =COUNTIF('Task Tracker'!$O$4:$O$53,D15)

Sheet Change Log
A1: 📋 Change Log & Update History
A2: # | B2: Date | C2: Task ID | D2: Changed By | E2: Change Type | F2: Old Value | G2: New Value | H2: Comments
A3: 1
A4: 2
A5: 3
A6: 4
A7: 5
A8: 6
A9: 7
A10: 8
A11: 9
A12: 10
A13: 11
A14: 12
... A102: 100

Sheet Reference
A1: 📌 Reference & Legend
A3: PRIORITY LEVELS | C3: TASK CATEGORIES
A4: Critical | B4: Blocking – system down; resolve immediately | C4: Bug Fix | D4: Defect repair in existing functionality
A5: High | B5: Major impact; resolve within 24–48 hours | C5: New Feature | D5: Brand-new functionality development
A6: Medium | B6: Partial impact; resolve within the sprint | C6: Enhancement | D6: Improvement to an existing feature
A7: Low | B7: Minor / cosmetic; resolve when bandwidth allows | C7: Performance | D7: Speed / resource optimisation
C8: Security | D8: Vulnerability fix or security hardening
A9: STATUS DESCRIPTIONS | C9: Content | D9: Text, media, or CMS content updates
A10: Pending | B10: Not yet started in this environment | C10: Infrastructure | D10: Server, hosting, CI/CD, DevOps tasks
A11: In Progress | B11: Being developed or deployed | C11: Database | D11: Schema changes, migrations, query tuning
A12: Deployed | B12: Successfully deployed | C12: Integration | D12: Third-party API or service connections
A13: Failed | B13: Deployment/execution failed | C13: Documentation | D13: Technical or user-facing documentation
A14: Rolled Back | B14: Reverted to previous stable version
A15: Hotfix Applied | B15: Emergency hotfix applied to production
